<?xml version="1.0" encoding="utf-8"?>
<!-- This URDF was automatically created by SolidWorks to URDF Exporter! Originally created by Stephen Brawner (brawner@gmail.com) 
     Commit Version: 1.6.0-4-g7f85cfe  Build Version: 1.6.7995.38578
     For more information, please see http://wiki.ros.org/sw_urdf_exporter -->
<robot
  name="ManipulatorUrdf">
  <link
    name="base_link">
    <inertial>
      <origin
        xyz="-1.2256E-08 1.2202E-08 0.0092811"
        rpy="0 0 0" />
      <mass
        value="0.12859" />
      <inertia
        ixx="7.4554E-05"
        ixy="6.4665E-13"
        ixz="-5.3254E-12"
        iyy="7.4554E-05"
        iyz="-6.5777E-11"
        izz="0.00013797" />
    </inertial>
    <visual>
      <origin
        xyz="0 0 0"
        rpy="0 0 0" />
      <geometry>
        <mesh
          filename="package://Manipulator/meshes/base_link.STL" />
      </geometry>
      <material
        name="">
        <color
          rgba="1 1 1 1" />
      </material>
    </visual>
    <collision>
      <origin
        xyz="0 0 0"
        rpy="0 0 0" />
      <geometry>
        <mesh
          filename="package://Manipulator/meshes/base_link.STL" />
      </geometry>
    </collision>
  </link>
  <link
    name="link1">
    <inertial>
      <origin
        xyz="-1.8589E-08 0.0077584 -0.032346"
        rpy="0 0 0" />
      <mass
        value="0.12312" />
      <inertia
        ixx="0.00012685"
        ixy="-6.4514E-12"
        ixz="5.3361E-11"
        iyy="0.00013136"
        iyz="-2.0015E-05"
        izz="3.7374E-05" />
    </inertial>
    <visual>
      <origin
        xyz="0 0 0"
        rpy="0 0 0" />
      <geometry>
        <mesh
          filename="package://Manipulator/meshes/link1.STL" />
      </geometry>
      <material
        name="">
        <color
          rgba="1 1 1 1" />
      </material>
    </visual>
    <collision>
      <origin
        xyz="0 0 0"
        rpy="0 0 0" />
      <geometry>
        <mesh
          filename="package://Manipulator/meshes/link1.STL" />
      </geometry>
    </collision>
  </link>
  <joint
    name="joint1"
    type="revolute">
    <origin
      xyz="0 0 0.10319"
      rpy="0 0 0" />
    <parent
      link="base_link" />
    <child
      link="link1" />
    <axis
      xyz="0 0 1" />
    <limit
      effort="100"
      velocity="100" />
  </joint>
  <link
    name="link2">
    <inertial>
      <origin
        xyz="-1.68476417454492E-08 0.0317343543085794 0.00745949851290703"
        rpy="0 0 0" />
      <mass
        value="0.125495294944391" />
      <inertia
        ixx="0.000128102613852571"
        ixy="-5.22874941597132E-11"
        ixz="2.33703270568762E-11"
        iyy="3.80907213341547E-05"
        iyz="1.996738147207E-05"
        izz="0.000131914555403081" />
    </inertial>
    <visual>
      <origin
        xyz="0 0 0"
        rpy="0 0 0" />
      <geometry>
        <mesh
          filename="package://Manipulator/meshes/link2.STL" />
      </geometry>
      <material
        name="">
        <color
          rgba="1 1 1 1" />
      </material>
    </visual>
    <collision>
      <origin
        xyz="0 0 0"
        rpy="0 0 0" />
      <geometry>
        <mesh
          filename="package://Manipulator/meshes/link2.STL" />
      </geometry>
    </collision>
  </link>
  <joint
    name="joint2"
    type="revolute">
    <origin
      xyz="0 0 0"
      rpy="1.5707963267949 0 0" />
    <parent
      link="link1" />
    <child
      link="link2" />
    <axis
      xyz="0 0 -1" />
    <limit
      effort="100"
      velocity="100" />
  </joint>
  <link
    name="link3">
    <inertial>
      <origin
        xyz="-1.23437792444076E-08 0.00885187226136737 -0.0593498418344666"
        rpy="0 0 0" />
      <mass
        value="0.162649767092968" />
      <inertia
        ixx="0.000384901372328097"
        ixy="4.07977784962619E-13"
        ixz="-6.61204349890713E-11"
        iyy="0.000394315089859218"
        iyz="-3.59136506465117E-05"
        izz="4.68839643301925E-05" />
    </inertial>
    <visual>
      <origin
        xyz="0 0 0"
        rpy="0 0 0" />
      <geometry>
        <mesh
          filename="package://Manipulator/meshes/link3.STL" />
      </geometry>
      <material
        name="">
        <color
          rgba="1 1 1 1" />
      </material>
    </visual>
    <collision>
      <origin
        xyz="0 0 0"
        rpy="0 0 0" />
      <geometry>
        <mesh
          filename="package://Manipulator/meshes/link3.STL" />
      </geometry>
    </collision>
  </link>
  <joint
    name="joint3"
    type="revolute">
    <origin
      xyz="0 0.2047875 0"
      rpy="-1.5707963267949 0 0" />
    <parent
      link="link2" />
    <child
      link="link3" />
    <axis
      xyz="0 0 1" />
    <limit
      effort="100"
      velocity="100" />
  </joint>
  <link
    name="link4">
    <inertial>
      <origin
        xyz="-2.23906566845296E-08 0.0317343152974587 0.00745949851290702"
        rpy="0 0 0" />
      <mass
        value="0.125495294944391" />
      <inertia
        ixx="0.000128102613982611"
        ixy="-5.19540681067498E-11"
        ixz="-4.06975266435014E-11"
        iyy="3.80907212041146E-05"
        iyz="1.99672577369089E-05"
        izz="0.00013191455540308" />
    </inertial>
    <visual>
      <origin
        xyz="0 0 0"
        rpy="0 0 0" />
      <geometry>
        <mesh
          filename="package://Manipulator/meshes/link4.STL" />
      </geometry>
      <material
        name="">
        <color
          rgba="1 1 1 1" />
      </material>
    </visual>
    <collision>
      <origin
        xyz="0 0 0"
        rpy="0 0 0" />
      <geometry>
        <mesh
          filename="package://Manipulator/meshes/link4.STL" />
      </geometry>
    </collision>
  </link>
  <joint
    name="joint4"
    type="revolute">
    <origin
      xyz="0 0 0"
      rpy="1.5707963267949 0 0" />
    <parent
      link="link3" />
    <child
      link="link4" />
    <axis
      xyz="0 0 -1" />
    <limit
      effort="100"
      velocity="100" />
  </joint>
  <link
    name="link5">
    <inertial>
      <origin
        xyz="-1.47136134640532E-09 0.00885185273884695 -0.059349841825483"
        rpy="0 0 0" />
      <mass
        value="0.162649767077565" />
      <inertia
        ixx="0.000384901369108547"
        ixy="5.87523367775495E-13"
        ixz="-3.11948432415529E-11"
        iyy="0.000394315093078619"
        iyz="-3.59137084063457E-05"
        izz="4.68839643301035E-05" />
    </inertial>
    <visual>
      <origin
        xyz="0 0 0"
        rpy="0 0 0" />
      <geometry>
        <mesh
          filename="package://Manipulator/meshes/link5.STL" />
      </geometry>
      <material
        name="">
        <color
          rgba="1 1 1 1" />
      </material>
    </visual>
    <collision>
      <origin
        xyz="0 0 0"
        rpy="0 0 0" />
      <geometry>
        <mesh
          filename="package://Manipulator/meshes/link5.STL" />
      </geometry>
    </collision>
  </link>
  <joint
    name="joint5"
    type="revolute">
    <origin
      xyz="0 0.2047875 0"
      rpy="-1.5707963267949 0 0" />
    <parent
      link="link4" />
    <child
      link="link5" />
    <axis
      xyz="0 0 1" />
    <limit
      effort="100"
      velocity="100" />
  </joint>
  <link
    name="link6">
    <inertial>
      <origin
        xyz="8.84933874646125E-10 0.0317343149617446 0.00745949851290702"
        rpy="0 0 0" />
      <mass
        value="0.125495294944391" />
      <inertia
        ixx="0.000128102615380365"
        ixy="-5.46457686055562E-11"
        ixz="2.70800504360073E-11"
        iyy="3.80907198063605E-05"
        iyz="1.99672602664282E-05"
        izz="0.000131914555403081" />
    </inertial>
    <visual>
      <origin
        xyz="0 0 0"
        rpy="0 0 0" />
      <geometry>
        <mesh
          filename="package://Manipulator/meshes/link6.STL" />
      </geometry>
      <material
        name="">
        <color
          rgba="1 1 1 1" />
      </material>
    </visual>
    <collision>
      <origin
        xyz="0 0 0"
        rpy="0 0 0" />
      <geometry>
        <mesh
          filename="package://Manipulator/meshes/link6.STL" />
      </geometry>
    </collision>
  </link>
  <joint
    name="joint6"
    type="revolute">
    <origin
      xyz="0 0 0"
      rpy="1.5708 0 0" />
    <parent
      link="link5" />
    <child
      link="link6" />
    <axis
      xyz="0 0 -1" />
    <limit
      effort="100"
      velocity="100" />
  </joint>
  <link
    name="link7">
    <inertial>
      <origin
        xyz="5.87774322886141E-08 5.34790418486022E-09 -0.0133863430450704"
        rpy="0 0 0" />
      <mass
        value="0.0477760977622199" />
      <inertia
        ixx="1.03742535103201E-05"
        ixy="-1.05535573516774E-12"
        ixz="6.27195878369067E-11"
        iyy="1.03742502286753E-05"
        iyz="-3.28525526936015E-11"
        izz="1.48894457745127E-05" />
    </inertial>
    <visual>
      <origin
        xyz="0 0 0"
        rpy="0 0 0" />
      <geometry>
        <mesh
          filename="package://Manipulator/meshes/link7.STL" />
      </geometry>
      <material
        name="">
        <color
          rgba="1 1 1 1" />
      </material>
    </visual>
    <collision>
      <origin
        xyz="0 0 0"
        rpy="0 0 0" />
      <geometry>
        <mesh
          filename="package://Manipulator/meshes/link7.STL" />
      </geometry>
    </collision>
  </link>
  <joint
    name="joint7"
    type="revolute">
    <origin
      xyz="0 0.10319 0"
      rpy="-1.5708 0 0" />
    <parent
      link="link6" />
    <child
      link="link7" />
    <axis
      xyz="0 0 1" />
    <limit
      effort="100"
      velocity="100" />
  </joint>
</robot>
